Workbook
Name PRate: #REF!
Name remarks: 'COMBO BOX OPS'!$C$2:$C$7
Name SchoolYear: 'COMBO BOX OPS'!$B$2:$B$4
Name Semester: 'COMBO BOX OPS'!$A$2:$A$3

Sheet Midterm OVPAA-F-INS-055A RAW SC
E1: 94
E2: BUKIDNON STATE UNIVERSITY
E3: Malaybalay City, Bukidnon 8700
E4: Tel (088) 813-5661 to 5663; TeleFax (088) 813-2717, www.buksu.edu.ph
E7: Section Code: | G7: T40 | I7: Day: | K7: TF
E8: Subject Code: | G8: DA 142 | I8: Time: | K8: 7:30AM-10:00AM
E9: Descriptive Title: | G9: Animation Design and Production | I9: Rm: | K9: Lab 7
E10: Semester: | G10: 1st Sem | I10: Units: | K10: 3 | S10: Department: | V10: Information Technology
E11: School Year: | G11: 2025-2026 | I11: Dept. Head: | K11: Dr. Sales G. Aribe, Jr. | S11: College: | V11: College of Technologies
E12: Instructor: | G12: Czarissa Louise A. Navidad | I12: Dean: | K12: Dr. Marilou O. Espina | S12: Passing Rate: | V12: 0.5
E13: Ctrl No | F13: ID Number | G13: NAME | H13: Class Standing | BU13: Laboratory | CO13: Major Output
H15: 1 | I15: 2 | J15: 3 | K15: 4 | L15: 5 | M15: 6 | N15: 7 | O15: 8 | P15: 9 | Q15: 10 | R15: 11 | S15: 12 | T15: 13 | U15: 14 | V15: 15 | W15: 16 | X15: 17 | Y15: 18 | Z15: 19 | AA15: 20 | AB15: 21 | AC15: 22 | AD15: 23 | AE15: 24 | AF15: 25 | AG15: 26 | AH15: 27 | AI15: 28 | AJ15: 29 | AK15: 30 | AL15: 31 | AM15: 32 | AN15: 33 | AO15: 34 | AP15: 35 | AQ15: 36 | AR15: 37 | AS15: 38 | AT15: 39 | AU15: 40 | AV15: 41 | AW15: 42 | AX15: 43 | AY15: 44 | AZ15: 45 | BA15: 46 | BB15: 47 | BC15: 48 | BD15: 49 | BE15: 50 | BF15: 51 | BG15: 52 | BH15: 53 | BI15: 54 | BJ15: 55 | BK15: 56 | BL15: 57 | BM15: 58 | BN15: 59 | BO15: 60 | BP15: 61 | BQ15: 62 | BR15: 63 | BS15: 64 | BT15: 65 | BU15: 1 | BV15: 2 | BW15: 3 | BX15: 4 | BY15: 5 | BZ15: 6 | CA15: 7 | CB15: 8 | CC15: 9 | CD15: 10 | CE15: 11 | CF15: 12 | CG15: 13 | CH15: 14 | CI15: 15 | CJ15: 16 | CK15: 17 | CL15: 18 | CM15: 19 | CN15: 20 | CO15: 1 | CP15: 2 | CQ15: 3 | CR15: 4 | CS15: 5 | CT15: 6 | CU15: 7 | CV15: 8 | CW15: 9 | CX15: 10
H16: Short Film Proposal | I16: Storyboard | J16: Long Quiz | BU16: Draft Script | BV16: Character Design | BW16: Background Design | CO16: Final Script | CP16: Midterm Exam
H17: 100 | I17: 100 | J17: 50 | BU17: 100 | BV17: 100 | BW17: 100 | CO17: 100 | CP17: 50
E18: 1 | F18: 2201103564 | G18: Albarracin, Donna Igar | H18: 80 | I18: 94 | J18: 42 | BU18: 80 | BV18: 100 | BW18: 100 | CO18: 92 | CP18: 38
E19: 2 | F19: 2201109992 | G19: Añonuevo, Thomas Franz | H19: 70 | I19: 92 | J19: 43 | BU19: 70 | BV19: 100 | BW19: 100 | CO19: 76 | CP19: 45
E20: 3 | F20: 2001102089 | G20: Cabuco, Dean Krist A. | H20: 94 | I20: 93 | J20: 44 | BU20: 94 | BV20: 100 | BW20: 100 | CO20: 94 | CP20: 44
E21: 4 | F21: 2201105829 | G21: De Guzman, Jim Dale Manong | H21: 72 | I21: 60 | J21: 0 | BU21: 72 | BV21: 100 | BW21: 75 | CO21: 72 | CP21: 36
E22: 5 | F22: 2201103056 | G22: Dela Cerna, Johann Derek Javier | H22: 70 | I22: 92 | J22: 45 | BU22: 70 | BV22: 100 | BW22: 100 | CO22: 76 | CP22: 43
E23: 6 | F23: 2201100446 | G23: Delfin, Kyle Arnie Jopson | H23: 80 | I23: 94 | J23: 42 | BU23: 80 | BV23: 100 | BW23: 100 | CO23: 92 | CP23: 40
E24: 7 | F24: 1801101449 | G24: Gumapac, Jannerie | H24: 72 | I24: 60 | J24: 50 | BU24: 72 | BV24: 100 | BW24: 80 | CO24: 72 | CP24: 35
E25: 8 | F25: 2201104090 | G25: Lantinay, Pol Edison | H25: 80 | I25: 94 | J25: 42 | BU25: 80 | BV25: 100 | BW25: 100 | CO25: 92 | CP25: 40
E26: 9 | F26: 2201100596 | G26: Lintawahan, Maria Elisabeth | H26: 72 | I26: 60 | J26: 0 | BU26: 72 | BV26: 100 | BW26: 75 | CO26: 72 | CP26: 45
E27: 10 | F27: 1801104290 | G27: Lisondra, Christian Earl | H27: 72 | I27: 60 | J27: 40 | BU27: 72 | BV27: 100 | BW27: 80 | CO27: 72 | CP27: 33
E28: 11 | F28: 2201104808 | G28: Magante, Jerson | H28: 72 | I28: 60 | J28: 0 | BU28: 72 | BV28: 100 | BW28: 75 | CO28: 72 | CP28: 40
E29: 12 | F29: 1801102006 | G29: Maraon, EJ Kate | H29: 72 | I29: 60 | J29: 50 | BU29: 72 | BV29: 100 | BW29: 80 | CO29: 72 | CP29: 40
... E40: 23 | F40: 2201108251 | G40: Valdez, John Winchel | H40: 70 | I40: 92 | J40: 0 | BU40: 70 | BV40: 100 | BW40: 100 | CO40: 76 | CP40: 40
E41: 24
E42: 25
E43: 26
E44: 27
E45: 28
E46: 29
E47: 30
E48: 31
E49: 32
E50: 33
E51: 34
E52: 35
... E117: 100

Sheet MidTerm OVPAA-F-INS-055B CLASS
F2: BUKIDNON STATE UNIVERSITY
F3: Malaybalay City, Bukidnon 8700
F4: Tel (088) 813-5661 to 5663; TeleFax (088) 813-2717, www.buksu.edu.ph
F6: CLASS RECORD
E7: Section Code: | G7: ='Midterm OVPAA-F-INS-055A RAW SC'!G7 -> T40 | I7: Day: | K7: ='Midterm OVPAA-F-INS-055A RAW SC'!K7 -> TF
E8: Subject Code: | G8: ='Midterm OVPAA-F-INS-055A RAW SC'!G8 -> DA 142 | I8: Time: | K8: ='Midterm OVPAA-F-INS-055A RAW SC'!K8 -> 7:30AM-10:00AM
E9: Descriptive Title: | G9: ='Midterm OVPAA-F-INS-055A RAW SC'!G9 -> Animation Design and Production | I9: Rm: | K9: ='Midterm OVPAA-F-INS-055A RAW SC'!K9 -> Lab 7
E10: Semester: | G10: ='Midterm OVPAA-F-INS-055A RAW SC'!G10 -> 1st Sem | I10: Units: | K10: ='Midterm OVPAA-F-INS-055A RAW SC'!K10 -> 3 | S10: Department: | V10: ='Midterm OVPAA-F-INS-055A RAW SC'!V10 -> Information Technology
E11: School Year: | G11: ='Midterm OVPAA-F-INS-055A RAW SC'!G11 -> 2025-2026 | I11: Chair: | K11: ='Midterm OVPAA-F-INS-055A RAW SC'!K11 -> Dr. Sales G. Aribe, Jr. | S11: College: | V11: ='Midterm OVPAA-F-INS-055A RAW SC'!V11 -> College of Technologies
E12: Instructor: | G12: ='Midterm OVPAA-F-INS-055A RAW SC'!G12 -> Czarissa Louise A. Navidad | I12: Dean: | K12: ='Midterm OVPAA-F-INS-055A RAW SC'!K12 -> Dr. Marilou O. Espina | S12: Passing Rate: | V12: ='Midterm OVPAA-F-INS-055A RAW SC'!V12 -> 0.5
E13: Ctrl No | F13: ID Number | G13: NAME | H13: Class Standing | BW13: Laboratory | CS13: Major Output | DE13: SUMMARY | DH13: MIDTERM GRADE
DE14: CS | DF14: LAB | DG14: MO
H15: 1 | I15: 2 | J15: 3 | K15: 4 | L15: 5 | M15: 6 | N15: 7 | O15: 8 | P15: 9 | Q15: 10 | R15: 11 | S15: 12 | T15: 13 | U15: 14 | V15: 15 | W15: 16 | X15: 17 | Y15: 18 | Z15: 19 | AA15: 20 | AB15: 21 | AC15: 22 | AD15: 23 | AE15: 24 | AF15: 25 | AG15: 26 | AH15: 27 | AI15: 28 | AJ15: 29 | AK15: 30 | AL15: 31 | AM15: 32 | AN15: 33 | AO15: 34 | AP15: 35 | AQ15: 36 | AR15: 37 | AS15: 38 | AT15: 39 | AU15: 40 | AV15: 41 | AW15: 42 | AX15: 43 | AY15: 44 | AZ15: 45 | BA15: 46 | BB15: 47 | BC15: 48 | BD15: 49 | BE15: 50 | BF15: 51 | BG15: 52 | BH15: 53 | BI15: 54 | BJ15: 55 | BK15: 56 | BL15: 57 | BM15: 58 | BN15: 59 | BO15: 60 | BP15: 61 | BQ15: 62 | BR15: 63 | BS15: 64 | BT15: 65 | BU15: GPA | BV15: EQUI | BW15: 1 | BX15: 2 | BY15: 3 | BZ15: 4 | CA15: 5 | CB15: 6 | CC15: 7 | CD15: 8 | CE15: 9 | CF15: 10 | CG15: 11 | CH15: 12 | CI15: 13 | CJ15: 14 | CK15: 15 | CL15: 16 | CM15: 17 | CN15: 18 | CO15: 19 | CP15: 20 | CQ15: GPA | CS15: 1 | CT15: 2 | CU15: 3 | CV15: 4 | CW15: 5 | CX15: 6 | CY15: 7 | CZ15: 8 | DA15: 9 | DB15: 10 | DC15: GPA | DD15: EQUI | DE15: 0.3 | DF15: 0.3 | DG15: 0.4 | DH15: TOTAL | DI15: FG
H16: =IF('Midterm OVPAA-F-INS-055A RAW SC'!H16="","",'Midterm OVPAA-F-INS-055A RAW SC'!H16) -> Short Film Proposal | I16: =IF('Midterm OVPAA-F-INS-055A RAW SC'!I16="","",'Midterm OVPAA-F-INS-055A RAW SC'!I16) -> Storyboard | J16: =IF('Midterm OVPAA-F-INS-055A RAW SC'!J16="","",'Midterm OVPAA-F-INS-055A RAW SC'!J16) -> Long Quiz | K16: =IF('Midterm OVPAA-F-INS-055A RAW SC'!K16="","",'Midterm OVPAA-F-INS-055A RAW SC'!K16) | L16: =IF('Midterm OVPAA-F-INS-055A RAW SC'!L16="","",'Midterm OVPAA-F-INS-055A RAW SC'!L16) | M16: =IF('Midterm OVPAA-F-INS-055A RAW SC'!M16="","",'Midterm OVPAA-F-INS-055A RAW SC'!M16) | N16: =IF('Midterm OVPAA-F-INS-055A RAW SC'!N16="","",'Midterm OVPAA-F-INS-055A RAW SC'!N16) | O16: =IF('Midterm OVPAA-F-INS-055A RAW SC'!O16="","",'Midterm OVPAA-F-INS-055A RAW SC'!O16) | ... BT16: =IF('Midterm OVPAA-F-INS-055A RAW SC'!BT16="","",'Midterm OVPAA-F-INS-055A RAW SC'!BT16) | BW16: =IF('Midterm OVPAA-F-INS-055A RAW SC'!BU16="","",'Midterm OVPAA-F-INS-055A RAW SC'!BU16) -> Draft Script | BX16: =IF('Midterm OVPAA-F-INS-055A RAW SC'!BV16="","",'Midterm OVPAA-F-INS-055A RAW SC'!BV16) -> Character Design | BY16: =IF('Midterm OVPAA-F-INS-055A RAW SC'!BW16="","",'Midterm OVPAA-F-INS-055A RAW SC'!BW16) -> Background Design | BZ16: =IF('Midterm OVPAA-F-INS-055A RAW SC'!BX16="","",'Midterm OVPAA-F-INS-055A RAW SC'!BX16) | CA16: =IF('Midterm OVPAA-F-INS-055A RAW SC'!BY16="","",'Midterm OVPAA-F-INS-055A RAW SC'!BY16) | CB16: =IF('Midterm OVPAA-F-INS-055A RAW SC'!BZ16="","",'Midterm OVPAA-F-INS-055A RAW SC'!BZ16) | CC16: =IF('Midterm OVPAA-F-INS-055A RAW SC'!CA16="","",'Midterm OVPAA-F-INS-055A RAW SC'!CA16) | CD16: =IF('Midterm OVPAA-F-INS-055A RAW SC'!CB16="","",'Midterm OVPAA-F-INS-055A RAW SC'!CB16) | ... CP16: =IF('Midterm OVPAA-F-INS-055A RAW SC'!CN16="","",'Midterm OVPAA-F-INS-055A RAW SC'!CN16) | CR16: EQUIVALENT | CS16: =IF('Midterm OVPAA-F-INS-055A RAW SC'!CO16="","",'Midterm OVPAA-F-INS-055A RAW SC'!CO16) -> Final Script | CT16: =IF('Midterm OVPAA-F-INS-055A RAW SC'!CP16="","",'Midterm OVPAA-F-INS-055A RAW SC'!CP16) -> Midterm Exam | CU16: =IF('Midterm OVPAA-F-INS-055A RAW SC'!CQ16="","",'Midterm OVPAA-F-INS-055A RAW SC'!CQ16) | CV16: =IF('Midterm OVPAA-F-INS-055A RAW SC'!CR16="","",'Midterm OVPAA-F-INS-055A RAW SC'!CR16) | CW16: =IF('Midterm OVPAA-F-INS-055A RAW SC'!CS16="","",'Midterm OVPAA-F-INS-055A RAW SC'!CS16) | CX16: =IF('Midterm OVPAA-F-INS-055A RAW SC'!CT16="","",'Midterm OVPAA-F-INS-055A RAW SC'!CT16) | CY16: =IF('Midterm OVPAA-F-INS-055A RAW SC'!CU16="","",'Midterm OVPAA-F-INS-055A RAW SC'!CU16) | CZ16: =IF('Midterm OVPAA-F-INS-055A RAW SC'!CV16="","",'Midterm OVPAA-F-INS-055A RAW SC'!CV16) | ... DB16: =IF('Midterm OVPAA-F-INS-055A RAW SC'!CX16="","",'Midterm OVPAA-F-INS-055A RAW SC'!CX16)
H17: GPE | I17: GPE | J17: GPE | K17: GPE | L17: GPE | M17: GPE | N17: GPE | O17: GPE | P17: GPE | Q17: GPE | R17: GPE | S17: GPE | T17: GPE | U17: GPE | V17: GPE | W17: GPE | X17: GPE | Y17: GPE | Z17: GPE | AA17: GPE | AB17: GPE | AC17: GPE | AD17: GPE | AE17: GPE | AF17: GPE | AG17: GPE | AH17: GPE | AI17: GPE | AJ17: GPE | AK17: GPE | AL17: GPE | AM17: GPE | AN17: GPE | AO17: GPE | AP17: GPE | AQ17: GPE | AR17: GPE | AS17: GPE | AT17: GPE | AU17: GPE | AV17: GPE | AW17: GPE | AX17: GPE | AY17: GPE | AZ17: GPE | BA17: GPE | BB17: GPE | BC17: GPE | BD17: GPE | BE17: GPE | BF17: GPE | BG17: GPE | BH17: GPE | BI17: GPE | BJ17: GPE | BK17: GPE | BL17: GPE | BM17: GPE | BN17: GPE | BO17: GPE | BP17: GPE | BQ17: GPE | BR17: GPE | BS17: GPE | BT17: GPE | BU17: 100 | BV17: 1 | BW17: GPE | BX17: GPE | BY17: GPE | BZ17: GPE | CA17: GPE | CB17: GPE | CC17: GPE | CD17: GPE | CE17: GPE | CF17: GPE | CG17: GPE | CH17: GPE | CI17: GPE | CJ17: GPE | CK17: GPE | CL17: GPE | CM17: GPE | CN17: GPE | CO17: GPE | CP17: GPE | CQ17: 100 | CR17: 1 | CS17: GPE | CT17: GPE | CU17: GPE | CV17: GPE | CW17: GPE | CX17: GPE | CY17: GPE | CZ17: GPE | DA17: GPE | DB17: GPE | DC17: 100 | DD17: 1 | DE17: =DE15 -> 0.3 | DF17: =DF15 -> 0.3 | DG17: =DG15 -> 0.4 | DH17: 100 | DI17: 1
E18: 1 | F18: =IF(NOT(ISBLANK('Midterm OVPAA-F-INS-055A RAW SC'!F18)),'Midterm OVPAA-F-INS-055A RAW SC'!F18,"") -> 2201103564 | G18: =IF(NOT(ISBLANK('Midterm OVPAA-F-INS-055A RAW SC'!G18)),'Midterm OVPAA-F-INS-055A RAW SC'!G18,"") -> Albarracin, Donna Igar | H18: =IF('Midterm OVPAA-F-INS-055A RAW SC'!H18="","",'Midterm OVPAA-F-INS-055A RAW SC'!H18/'Midterm OVPAA-F-INS-055A RAW SC'!H$17*100) -> 80 | I18: =IF('Midterm OVPAA-F-INS-055A RAW SC'!I18="","",'Midterm OVPAA-F-INS-055A RAW SC'!I18/'Midterm OVPAA-F-INS-055A RAW SC'!I$17*100) -> 94 | J18: =IF('Midterm OVPAA-F-INS-055A RAW SC'!J18="","",'Midterm OVPAA-F-INS-055A RAW SC'!J18/'Midterm OVPAA-F-INS-055A RAW SC'!J$17*100) -> 84 | K18: =IF('Midterm OVPAA-F-INS-055A RAW SC'!K18="","",'Midterm OVPAA-F-INS-055A RAW SC'!K18/'Midterm OVPAA-F-INS-055A RAW SC'!K$17*100) | L18: =IF('Midterm OVPAA-F-INS-055A RAW SC'!L18="","",'Midterm OVPAA-F-INS-055A RAW SC'!L18/'Midterm OVPAA-F-INS-055A RAW SC'!L$17*100) | M18: =IF('Midterm OVPAA-F-INS-055A RAW SC'!M18="","",'Midterm OVPAA-F-INS-055A RAW SC'!M18/'Midterm OVPAA-F-INS-055A RAW SC'!M$17*100) | N18: =IF('Midterm OVPAA-F-INS-055A RAW SC'!N18="","",'Midterm OVPAA-F-INS-055A RAW SC'!N18/'Midterm OVPAA-F-INS-055A RAW SC'!N$17*100) | O18: =IF('Midterm OVPAA-F-INS-055A RAW SC'!O18="","",'Midterm OVPAA-F-INS-055A RAW SC'!O18/'Midterm OVPAA-F-INS-055A RAW SC'!O$17*100) | ... BT18: =IF('Midterm OVPAA-F-INS-055A RAW SC'!BT18="","",'Midterm OVPAA-F-INS-055A RAW SC'!BT18/'Midterm OVPAA-F-INS-055A RAW SC'!BT$17*100) | BU18: {=IF('Midterm OVPAA-F-INS-055A RAW SC'!$G18="","",IF((SUMPRODUCT(--ISBLANK('Midterm OVPAA-F-INS-055A RAW SC'!H18:BT18))=COLUMNS('Midterm OVPAA-F-INS-055A RAW SC'!H18:BT18))=TRUE,"",(((COUNTA('Midterm OVPAA-F-INS-055A RAW SC'!$H$17:$BT$17)+COUNTBLANK('Midterm OVPAA-F-INS-055A RAW SC'!H18:BT18))-COLUMNS('Midterm OVPAA-F-INS-055A RAW SC'!H18:BT18))*5+SUM(H18:BT18))/COUNTA('Midterm OVPAA-F-INS-055A RAW SC'!$H$17:$BT$17)))} -> 86 | BV18: =IF(BU18="","",VLOOKUP(BU18,IF('Midterm OVPAA-F-INS-055A RAW SC'!$V$12=0.5,TRANSMUTATION!$C$4:$D$17,TRANSMUTATION!$G$4:$H$17),2,TRUE)) -> 1.5 | BW18: =IF('Midterm OVPAA-F-INS-055A RAW SC'!BU18="","",'Midterm OVPAA-F-INS-055A RAW SC'!BU18/'Midterm OVPAA-F-INS-055A RAW SC'!BU$17*100) -> 80 | BX18: =IF('Midterm OVPAA-F-INS-055A RAW SC'!BV18="","",'Midterm OVPAA-F-INS-055A RAW SC'!BV18/'Midterm OVPAA-F-INS-055A RAW SC'!BV$17*100) -> 100 | BY18: =IF('Midterm OVPAA-F-INS-055A RAW SC'!BW18="","",'Midterm OVPAA-F-INS-055A RAW SC'!BW18/'Midterm OVPAA-F-INS-055A RAW SC'!BW$17*100) -> 100 | BZ18: =IF('Midterm OVPAA-F-INS-055A RAW SC'!BX18="","",'Midterm OVPAA-F-INS-055A RAW SC'!BX18/'Midterm OVPAA-F-INS-055A RAW SC'!BX$17*100) | CA18: =IF('Midterm OVPAA-F-INS-055A RAW SC'!BY18="","",'Midterm OVPAA-F-INS-055A RAW SC'!BY18/'Midterm OVPAA-F-INS-055A RAW SC'!BY$17*100) | CB18: =IF('Midterm OVPAA-F-INS-055A RAW SC'!BZ18="","",'Midterm OVPAA-F-INS-055A RAW SC'!BZ18/'Midterm OVPAA-F-INS-055A RAW SC'!BZ$17*100) | CC18: =IF('Midterm OVPAA-F-INS-055A RAW SC'!CA18="","",'Midterm OVPAA-F-INS-055A RAW SC'!CA18/'Midterm OVPAA-F-INS-055A RAW SC'!CA$17*100) | CD18: =IF('Midterm OVPAA-F-INS-055A RAW SC'!CB18="","",'Midterm OVPAA-F-INS-055A RAW SC'!CB18/'Midterm OVPAA-F-INS-055A RAW SC'!CB$17*100) | ... CP18: =IF('Midterm OVPAA-F-INS-055A RAW SC'!CN18="","",'Midterm OVPAA-F-INS-055A RAW SC'!CN18/'Midterm OVPAA-F-INS-055A RAW SC'!CN$17*100) | CQ18: {=IF('Midterm OVPAA-F-INS-055A RAW SC'!G18="","",IF((SUMPRODUCT(--ISBLANK('Midterm OVPAA-F-INS-055A RAW SC'!BU18:CN18))=COLUMNS('Midterm OVPAA-F-INS-055A RAW SC'!BU18:CN18))=TRUE,"",(((COUNTA('Midterm OVPAA-F-INS-055A RAW SC'!$BU$17:$CN$17)+COUNTBLANK('Midterm OVPAA-F-INS-055A RAW SC'!BU18:CN18))-COLUMNS('Midterm OVPAA-F-INS-055A RAW SC'!BU18:CN18))*5+SUM(BW18:CP18))/COUNTA('Midterm OVPAA-F-INS-055A RAW SC'!$BU$17:$CN$17)))} -> 93.333333 | CR18: =IF(CQ18="","",VLOOKUP(CQ18,IF('Midterm OVPAA-F-INS-055A RAW SC'!$V$12=0.5,TRANSMUTATION!$C$4:$D$17,TRANSMUTATION!$G$4:$H$17),2,TRUE)) -> 1.25 | CS18: =IF('Midterm OVPAA-F-INS-055A RAW SC'!CO18="","",'Midterm OVPAA-F-INS-055A RAW SC'!CO18/'Midterm OVPAA-F-INS-055A RAW SC'!CO$17*100) -> 92 | CT18: =IF('Midterm OVPAA-F-INS-055A RAW SC'!CP18="","",'Midterm OVPAA-F-INS-055A RAW SC'!CP18/'Midterm OVPAA-F-INS-055A RAW SC'!CP$17*100) -> 76 | CU18: =IF('Midterm OVPAA-F-INS-055A RAW SC'!CQ18="","",'Midterm OVPAA-F-INS-055A RAW SC'!CQ18/'Midterm OVPAA-F-INS-055A RAW SC'!CQ$17*100) | CV18: =IF('Midterm OVPAA-F-INS-055A RAW SC'!CR18="","",'Midterm OVPAA-F-INS-055A RAW SC'!CR18/'Midterm OVPAA-F-INS-055A RAW SC'!CR$17*100) | CW18: =IF('Midterm OVPAA-F-INS-055A RAW SC'!CS18="","",'Midterm OVPAA-F-INS-055A RAW SC'!CS18/'Midterm OVPAA-F-INS-055A RAW SC'!CS$17*100) | CX18: =IF('Midterm OVPAA-F-INS-055A RAW SC'!CT18="","",'Midterm OVPAA-F-INS-055A RAW SC'!CT18/'Midterm OVPAA-F-INS-055A RAW SC'!CT$17*100) | CY18: =IF('Midterm OVPAA-F-INS-055A RAW SC'!CU18="","",'Midterm OVPAA-F-INS-055A RAW SC'!CU18/'Midterm OVPAA-F-INS-055A RAW SC'!CU$17*100) | CZ18: =IF('Midterm OVPAA-F-INS-055A RAW SC'!CV18="","",'Midterm OVPAA-F-INS-055A RAW SC'!CV18/'Midterm OVPAA-F-INS-055A RAW SC'!CV$17*100) | ... DB18: =IF('Midterm OVPAA-F-INS-055A RAW SC'!CX18="","",'Midterm OVPAA-F-INS-055A RAW SC'!CX18/'Midterm OVPAA-F-INS-055A RAW SC'!CX$17*100) | DC18: {=IF('Midterm OVPAA-F-INS-055A RAW SC'!$G18="","",IF((SUMPRODUCT(--ISBLANK('Midterm OVPAA-F-INS-055A RAW SC'!CO18:CX18))=COLUMNS('Midterm OVPAA-F-INS-055A RAW SC'!CO18:CX18))=TRUE,"",(((COUNTA('Midterm OVPAA-F-INS-055A RAW SC'!$CO$17:$CX$17)+COUNTBLANK('Midterm OVPAA-F-INS-055A RAW SC'!CO18:CX18))-COLUMNS('Midterm OVPAA-F-INS-055A RAW SC'!CO18:CX18))*5+SUM(CS18:DB18))/COUNTA('Midterm OVPAA-F-INS-055A RAW SC'!$CO$17:$CX$17)))} -> 84 | DD18: =IF(DC18="","",VLOOKUP(DC18,IF('Midterm OVPAA-F-INS-055A RAW SC'!$V$12=0.5,TRANSMUTATION!$C$4:$D$17,TRANSMUTATION!$G$4:$H$17),2,TRUE)) -> 1.75 | DE18: =IF(BV18="","",(BV18*DE$15)) -> 0.45 | DF18: =IF(CR18="","",(CR18*DF$15)) -> 0.375 | DG18: =IF(DD18="","",(DD18*DG$15)) -> 0.7 | DH18: =IF($DF$15="",IF(OR(DE18="",DG18="")=TRUE,"",(SUM(DE18:DG18))),IF(OR(DE18="",DF18="",DG18="")=TRUE,"",(SUM(DE18:DG18)))) -> 1.525 | DI18: =IF(DH18="","",LOOKUP(DH18,{0,1.1251,1.3751,1.6251,1.8751,2.1251,2.3751,2.6251,2.8751,3.1251,3.3751,3.6251},{"1.00","1.25","1.50","1.75","2.00","2.25","2.50","2.75","3.00","3.25","3.50","5.00"})) -> 1.50
E19: 2 | F19: =IF(NOT(ISBLANK('Midterm OVPAA-F-INS-055A RAW SC'!F19)),'Midterm OVPAA-F-INS-055A RAW SC'!F19,"") -> 2201109992 | G19: =IF(NOT(ISBLANK('Midterm OVPAA-F-INS-055A RAW SC'!G19)),'Midterm OVPAA-F-INS-055A RAW SC'!G19,"") -> Añonuevo, Thomas Franz | H19: =IF('Midterm OVPAA-F-INS-055A RAW SC'!H19="","",'Midterm OVPAA-F-INS-055A RAW SC'!H19/'Midterm OVPAA-F-INS-055A RAW SC'!H$17*100) -> 70 | I19: =IF('Midterm OVPAA-F-INS-055A RAW SC'!I19="","",'Midterm OVPAA-F-INS-055A RAW SC'!I19/'Midterm OVPAA-F-INS-055A RAW SC'!I$17*100) -> 92 | J19: =IF('Midterm OVPAA-F-INS-055A RAW SC'!J19="","",'Midterm OVPAA-F-INS-055A RAW SC'!J19/'Midterm OVPAA-F-INS-055A RAW SC'!J$17*100) -> 86 | K19: =IF('Midterm OVPAA-F-INS-055A RAW SC'!K19="","",'Midterm OVPAA-F-INS-055A RAW SC'!K19/'Midterm OVPAA-F-INS-055A RAW SC'!K$17*100) | L19: =IF('Midterm OVPAA-F-INS-055A RAW SC'!L19="","",'Midterm OVPAA-F-INS-055A RAW SC'!L19/'Midterm OVPAA-F-INS-055A RAW SC'!L$17*100) | M19: =IF('Midterm OVPAA-F-INS-055A RAW SC'!M19="","",'Midterm OVPAA-F-INS-055A RAW SC'!M19/'Midterm OVPAA-F-INS-055A RAW SC'!M$17*100) | N19: =IF('Midterm OVPAA-F-INS-055A RAW SC'!N19="","",'Midterm OVPAA-F-INS-055A RAW SC'!N19/'Midterm OVPAA-F-INS-055A RAW SC'!N$17*100) | O19: =IF('Midterm OVPAA-F-INS-055A RAW SC'!O19="","",'Midterm OVPAA-F-INS-055A RAW SC'!O19/'Midterm OVPAA-F-INS-055A RAW SC'!O$17*100) | ... BT19: =IF('Midterm OVPAA-F-INS-055A RAW SC'!BT19="","",'Midterm OVPAA-F-INS-055A RAW SC'!BT19/'Midterm OVPAA-F-INS-055A RAW SC'!BT$17*100) | BU19: {=IF('Midterm OVPAA-F-INS-055A RAW SC'!$G19="","",IF((SUMPRODUCT(--ISBLANK('Midterm OVPAA-F-INS-055A RAW SC'!H19:BT19))=COLUMNS('Midterm OVPAA-F-INS-055A RAW SC'!H19:BT19))=TRUE,"",(((COUNTA('Midterm OVPAA-F-INS-055A RAW SC'!$H$17:$BT$17)+COUNTBLANK('Midterm OVPAA-F-INS-055A RAW SC'!H19:BT19))-COLUMNS('Midterm OVPAA-F-INS-055A RAW SC'!H19:BT19))*5+SUM(H19:BT19))/COUNTA('Midterm OVPAA-F-INS-055A RAW SC'!$H$17:$BT$17)))} -> 82.666667 | BV19: =IF(BU19="","",VLOOKUP(BU19,IF('Midterm OVPAA-F-INS-055A RAW SC'!$V$12=0.5,TRANSMUTATION!$C$4:$D$17,TRANSMUTATION!$G$4:$H$17),2,TRUE)) -> 1.75 | BW19: =IF('Midterm OVPAA-F-INS-055A RAW SC'!BU19="","",'Midterm OVPAA-F-INS-055A RAW SC'!BU19/'Midterm OVPAA-F-INS-055A RAW SC'!BU$17*100) -> 70 | BX19: =IF('Midterm OVPAA-F-INS-055A RAW SC'!BV19="","",'Midterm OVPAA-F-INS-055A RAW SC'!BV19/'Midterm OVPAA-F-INS-055A RAW SC'!BV$17*100) -> 100 | BY19: =IF('Midterm OVPAA-F-INS-055A RAW SC'!BW19="","",'Midterm OVPAA-F-INS-055A RAW SC'!BW19/'Midterm OVPAA-F-INS-055A RAW SC'!BW$17*100) -> 100 | BZ19: =IF('Midterm OVPAA-F-INS-055A RAW SC'!BX19="","",'Midterm OVPAA-F-INS-055A RAW SC'!BX19/'Midterm OVPAA-F-INS-055A RAW SC'!BX$17*100) | CA19: =IF('Midterm OVPAA-F-INS-055A RAW SC'!BY19="","",'Midterm OVPAA-F-INS-055A RAW SC'!BY19/'Midterm OVPAA-F-INS-055A RAW SC'!BY$17*100) | CB19: =IF('Midterm OVPAA-F-INS-055A RAW SC'!BZ19="","",'Midterm OVPAA-F-INS-055A RAW SC'!BZ19/'Midterm OVPAA-F-INS-055A RAW SC'!BZ$17*100) | CC19: =IF('Midterm OVPAA-F-INS-055A RAW SC'!CA19="","",'Midterm OVPAA-F-INS-055A RAW SC'!CA19/'Midterm OVPAA-F-INS-055A RAW SC'!CA$17*100) | CD19: =IF('Midterm OVPAA-F-INS-055A RAW SC'!CB19="","",'Midterm OVPAA-F-INS-055A RAW SC'!CB19/'Midterm OVPAA-F-INS-055A RAW SC'!CB$17*100) | ... CP19: =IF('Midterm OVPAA-F-INS-055A RAW SC'!CN19="","",'Midterm OVPAA-F-INS-055A RAW SC'!CN19/'Midterm OVPAA-F-INS-055A RAW SC'!CN$17*100) | CQ19: {=IF('Midterm OVPAA-F-INS-055A RAW SC'!G19="","",IF((SUMPRODUCT(--ISBLANK('Midterm OVPAA-F-INS-055A RAW SC'!BU19:CN19))=COLUMNS('Midterm OVPAA-F-INS-055A RAW SC'!BU19:CN19))=TRUE,"",(((COUNTA('Midterm OVPAA-F-INS-055A RAW SC'!$BU$17:$CN$17)+COUNTBLANK('Midterm OVPAA-F-INS-055A RAW SC'!BU19:CN19))-COLUMNS('Midterm OVPAA-F-INS-055A RAW SC'!BU19:CN19))*5+SUM(BW19:CP19))/COUNTA('Midterm OVPAA-F-INS-055A RAW SC'!$BU$17:$CN$17)))} -> 90 | CR19: =IF(CQ19="","",VLOOKUP(CQ19,IF('Midterm OVPAA-F-INS-055A RAW SC'!$V$12=0.5,TRANSMUTATION!$C$4:$D$17,TRANSMUTATION!$G$4:$H$17),2,TRUE)) -> 1.5 | CS19: =IF('Midterm OVPAA-F-INS-055A RAW SC'!CO19="","",'Midterm OVPAA-F-INS-055A RAW SC'!CO19/'Midterm OVPAA-F-INS-055A RAW SC'!CO$17*100) -> 76 | CT19: =IF('Midterm OVPAA-F-INS-055A RAW SC'!CP19="","",'Midterm OVPAA-F-INS-055A RAW SC'!CP19/'Midterm OVPAA-F-INS-055A RAW SC'!CP$17*100) -> 90 | CU19: =IF('Midterm OVPAA-F-INS-055A RAW SC'!CQ19="","",'Midterm OVPAA-F-INS-055A RAW SC'!CQ19/'Midterm OVPAA-F-INS-055A RAW SC'!CQ$17*100) | CV19: =IF('Midterm OVPAA-F-INS-055A RAW SC'!CR19="","",'Midterm OVPAA-F-INS-055A RAW SC'!CR19/'Midterm OVPAA-F-INS-055A RAW SC'!CR$17*100) | CW19: =IF('Midterm OVPAA-F-INS-055A RAW SC'!CS19="","",'Midterm OVPAA-F-INS-055A RAW SC'!CS19/'Midterm OVPAA-F-INS-055A RAW SC'!CS$17*100) | CX19: =IF('Midterm OVPAA-F-INS-055A RAW SC'!CT19="","",'Midterm OVPAA-F-INS-055A RAW SC'!CT19/'Midterm OVPAA-F-INS-055A RAW SC'!CT$17*100) | CY19: =IF('Midterm OVPAA-F-INS-055A RAW SC'!CU19="","",'Midterm OVPAA-F-INS-055A RAW SC'!CU19/'Midterm OVPAA-F-INS-055A RAW SC'!CU$17*100) | CZ19: =IF('Midterm OVPAA-F-INS-055A RAW SC'!CV19="","",'Midterm OVPAA-F-INS-055A RAW SC'!CV19/'Midterm OVPAA-F-INS-055A RAW SC'!CV$17*100) | ... DB19: =IF('Midterm OVPAA-F-INS-055A RAW SC'!CX19="","",'Midterm OVPAA-F-INS-055A RAW SC'!CX19/'Midterm OVPAA-F-INS-055A RAW SC'!CX$17*100) | DC19: {=IF('Midterm OVPAA-F-INS-055A RAW SC'!$G19="","",IF((SUMPRODUCT(--ISBLANK('Midterm OVPAA-F-INS-055A RAW SC'!CO19:CX19))=COLUMNS('Midterm OVPAA-F-INS-055A RAW SC'!CO19:CX19))=TRUE,"",(((COUNTA('Midterm OVPAA-F-INS-055A RAW SC'!$CO$17:$CX$17)+COUNTBLANK('Midterm OVPAA-F-INS-055A RAW SC'!CO19:CX19))-COLUMNS('Midterm OVPAA-F-INS-055A RAW SC'!CO19:CX19))*5+SUM(CS19:DB19))/COUNTA('Midterm OVPAA-F-INS-055A RAW SC'!$CO$17:$CX$17)))} -> 83 | DD19: =IF(DC19="","",VLOOKUP(DC19,IF('Midterm OVPAA-F-INS-055A RAW SC'!$V$12=0.5,TRANSMUTATION!$C$4:$D$17,TRANSMUTATION!$G$4:$H$17),2,TRUE)) -> 1.75 | DE19: =IF(BV19="","",(BV19*DE$15)) -> 0.525 | DF19: =IF(CR19="","",(CR19*DF$15)) -> 0.45 | DG19: =IF(DD19="","",(DD19*DG$15)) -> 0.7 | DH19: =IF($DF$15="",IF(OR(DE19="",DG19="")=TRUE,"",(SUM(DE19:DG19))),IF(OR(DE19="",DF19="",DG19="")=TRUE,"",(SUM(DE19:DG19)))) -> 1.675 | DI19: =IF(DH19="","",LOOKUP(DH19,{0,1.1251,1.3751,1.6251,1.8751,2.1251,2.3751,2.6251,2.8751,3.1251,3.3751,3.6251},{"1.00","1.25","1.50","1.75","2.00","2.25","2.50","2.75","3.00","3.25","3.50","5.00"})) -> 1.75
E20: 3 | F20: =IF(NOT(ISBLANK('Midterm OVPAA-F-INS-055A RAW SC'!F20)),'Midterm OVPAA-F-INS-055A RAW SC'!F20,"") -> 2001102089 | G20: =IF(NOT(ISBLANK('Midterm OVPAA-F-INS-055A RAW SC'!G20)),'Midterm OVPAA-F-INS-055A RAW SC'!G20,"") -> Cabuco, Dean Krist A. | H20: =IF('Midterm OVPAA-F-INS-055A RAW SC'!H20="","",'Midterm OVPAA-F-INS-055A RAW SC'!H20/'Midterm OVPAA-F-INS-055A RAW SC'!H$17*100) -> 94 | I20: =IF('Midterm OVPAA-F-INS-055A RAW SC'!I20="","",'Midterm OVPAA-F-INS-055A RAW SC'!I20/'Midterm OVPAA-F-INS-055A RAW SC'!I$17*100) -> 93 | J20: =IF('Midterm OVPAA-F-INS-055A RAW SC'!J20="","",'Midterm OVPAA-F-INS-055A RAW SC'!J20/'Midterm OVPAA-F-INS-055A RAW SC'!J$17*100) -> 88 | K20: =IF('Midterm OVPAA-F-INS-055A RAW SC'!K20="","",'Midterm OVPAA-F-INS-055A RAW SC'!K20/'Midterm OVPAA-F-INS-055A RAW SC'!K$17*100) | L20: =IF('Midterm OVPAA-F-INS-055A RAW SC'!L20="","",'Midterm OVPAA-F-INS-055A RAW SC'!L20/'Midterm OVPAA-F-INS-055A RAW SC'!L$17*100) | M20: =IF('Midterm OVPAA-F-INS-055A RAW SC'!M20="","",'Midterm OVPAA-F-INS-055A RAW SC'!M20/'Midterm OVPAA-F-INS-055A RAW SC'!M$17*100) | N20: =IF('Midterm OVPAA-F-INS-055A RAW SC'!N20="","",'Midterm OVPAA-F-INS-055A RAW SC'!N20/'Midterm OVPAA-F-INS-055A RAW SC'!N$17*100) | O20: =IF('Midterm OVPAA-F-INS-055A RAW SC'!O20="","",'Midterm OVPAA-F-INS-055A RAW SC'!O20/'Midterm OVPAA-F-INS-055A RAW SC'!O$17*100) | ... BT20: =IF('Midterm OVPAA-F-INS-055A RAW SC'!BT20="","",'Midterm OVPAA-F-INS-055A RAW SC'!BT20/'Midterm OVPAA-F-INS-055A RAW SC'!BT$17*100) | BU20: {=IF('Midterm OVPAA-F-INS-055A RAW SC'!$G20="","",IF((SUMPRODUCT(--ISBLANK('Midterm OVPAA-F-INS-055A RAW SC'!H20:BT20))=COLUMNS('Midterm OVPAA-F-INS-055A RAW SC'!H20:BT20))=TRUE,"",(((COUNTA('Midterm OVPAA-F-INS-055A RAW SC'!$H$17:$BT$17)+COUNTBLANK('Midterm OVPAA-F-INS-055A RAW SC'!H20:BT20))-COLUMNS('Midterm OVPAA-F-INS-055A RAW SC'!H20:BT20))*5+SUM(H20:BT20))/COUNTA('Midterm OVPAA-F-INS-055A RAW SC'!$H$17:$BT$17)))} -> 91.666667 | BV20: =IF(BU20="","",VLOOKUP(BU20,IF('Midterm OVPAA-F-INS-055A RAW SC'!$V$12=0.5,TRANSMUTATION!$C$4:$D$17,TRANSMUTATION!$G$4:$H$17),2,TRUE)) -> 1.25 | BW20: =IF('Midterm OVPAA-F-INS-055A RAW SC'!BU20="","",'Midterm OVPAA-F-INS-055A RAW SC'!BU20/'Midterm OVPAA-F-INS-055A RAW SC'!BU$17*100) -> 94 | BX20: =IF('Midterm OVPAA-F-INS-055A RAW SC'!BV20="","",'Midterm OVPAA-F-INS-055A RAW SC'!BV20/'Midterm OVPAA-F-INS-055A RAW SC'!BV$17*100) -> 100 | BY20: =IF('Midterm OVPAA-F-INS-055A RAW SC'!BW20="","",'Midterm OVPAA-F-INS-055A RAW SC'!BW20/'Midterm OVPAA-F-INS-055A RAW SC'!BW$17*100) -> 100 | BZ20: =IF('Midterm OVPAA-F-INS-055A RAW SC'!BX20="","",'Midterm OVPAA-F-INS-055A RAW SC'!BX20/'Midterm OVPAA-F-INS-055A RAW SC'!BX$17*100) | CA20: =IF('Midterm OVPAA-F-INS-055A RAW SC'!BY20="","",'Midterm OVPAA-F-INS-055A RAW SC'!BY20/'Midterm OVPAA-F-INS-055A RAW SC'!BY$17*100) | CB20: =IF('Midterm OVPAA-F-INS-055A RAW SC'!BZ20="","",'Midterm OVPAA-F-INS-055A RAW SC'!BZ20/'Midterm OVPAA-F-INS-055A RAW SC'!BZ$17*100) | CC20: =IF('Midterm OVPAA-F-INS-055A RAW SC'!CA20="","",'Midterm OVPAA-F-INS-055A RAW SC'!CA20/'Midterm OVPAA-F-INS-055A RAW SC'!CA$17*100) | CD20: =IF('Midterm OVPAA-F-INS-055A RAW SC'!CB20="","",'Midterm OVPAA-F-INS-055A RAW SC'!CB20/'Midterm OVPAA-F-INS-055A RAW SC'!CB$17*100) | ... CP20: =IF('Midterm OVPAA-F-INS-055A RAW SC'!CN20="","",'Midterm OVPAA-F-INS-055A RAW SC'!CN20/'Midterm OVPAA-F-INS-055A RAW SC'!CN$17*100) | CQ20: {=IF('Midterm OVPAA-F-INS-055A RAW SC'!G20="","",IF((SUMPRODUCT(--ISBLANK('Midterm OVPAA-F-INS-055A RAW SC'!BU20:CN20))=COLUMNS('Midterm OVPAA-F-INS-055A RAW SC'!BU20:CN20))=TRUE,"",(((COUNTA('Midterm OVPAA-F-INS-055A RAW SC'!$BU$17:$CN$17)+COUNTBLANK('Midterm OVPAA-F-INS-055A RAW SC'!BU20:CN20))-COLUMNS('Midterm OVPAA-F-INS-055A RAW SC'!BU20:CN20))*5+SUM(BW20:CP20))/COUNTA('Midterm OVPAA-F-INS-055A RAW SC'!$BU$17:$CN$17)))} -> 98 | CR20: =IF(CQ20="","",VLOOKUP(CQ20,IF('Midterm OVPAA-F-INS-055A RAW SC'!$V$12=0.5,TRANSMUTATION!$C$4:$D$17,TRANSMUTATION!$G$4:$H$17),2,TRUE)) -> 1 | CS20: =IF('Midterm OVPAA-F-INS-055A RAW SC'!CO20="","",'Midterm OVPAA-F-INS-055A RAW SC'!CO20/'Midterm OVPAA-F-INS-055A RAW SC'!CO$17*100) -> 94 | CT20: =IF('Midterm OVPAA-F-INS-055A RAW SC'!CP20="","",'Midterm OVPAA-F-INS-055A RAW SC'!CP20/'Midterm OVPAA-F-INS-055A RAW SC'!CP$17*100) -> 88 | CU20: =IF('Midterm OVPAA-F-INS-055A RAW SC'!CQ20="","",'Midterm OVPAA-F-INS-055A RAW SC'!CQ20/'Midterm OVPAA-F-INS-055A RAW SC'!CQ$17*100) | CV20: =IF('Midterm OVPAA-F-INS-055A RAW SC'!CR20="","",'Midterm OVPAA-F-INS-055A RAW SC'!CR20/'Midterm OVPAA-F-INS-055A RAW SC'!CR$17*100) | CW20: =IF('Midterm OVPAA-F-INS-055A RAW SC'!CS20="","",'Midterm OVPAA-F-INS-055A RAW SC'!CS20/'Midterm OVPAA-F-INS-055A RAW SC'!CS$17*100) | CX20: =IF('Midterm OVPAA-F-INS-055A RAW SC'!CT20="","",'Midterm OVPAA-F-INS-055A RAW SC'!CT20/'Midterm OVPAA-F-INS-055A RAW SC'!CT$17*100) | CY20: =IF('Midterm OVPAA-F-INS-055A RAW SC'!CU20="","",'Midterm OVPAA-F-INS-055A RAW SC'!CU20/'Midterm OVPAA-F-INS-055A RAW SC'!CU$17*100) | CZ20: =IF('Midterm OVPAA-F-INS-055A RAW SC'!CV20="","",'Midterm OVPAA-F-INS-055A RAW SC'!CV20/'Midterm OVPAA-F-INS-055A RAW SC'!CV$17*100) | ... DB20: =IF('Midterm OVPAA-F-INS-055A RAW SC'!CX20="","",'Midterm OVPAA-F-INS-055A RAW SC'!CX20/'Midterm OVPAA-F-INS-055A RAW SC'!CX$17*100) | DC20: {=IF('Midterm OVPAA-F-INS-055A RAW SC'!$G20="","",IF((SUMPRODUCT(--ISBLANK('Midterm OVPAA-F-INS-055A RAW SC'!CO20:CX20))=COLUMNS('Midterm OVPAA-F-INS-055A RAW SC'!CO20:CX20))=TRUE,"",(((COUNTA('Midterm OVPAA-F-INS-055A RAW SC'!$CO$17:$CX$17)+COUNTBLANK('Midterm OVPAA-F-INS-055A RAW SC'!CO20:CX20))-COLUMNS('Midterm OVPAA-F-INS-055A RAW SC'!CO20:CX20))*5+SUM(CS20:DB20))/COUNTA('Midterm OVPAA-F-INS-055A RAW SC'!$CO$17:$CX$17)))} -> 91 | DD20: =IF(DC20="","",VLOOKUP(DC20,IF('Midterm OVPAA-F-INS-055A RAW SC'!$V$12=0.5,TRANSMUTATION!$C$4:$D$17,TRANSMUTATION!$G$4:$H$17),2,TRUE)) -> 1.25 | DE20: =IF(BV20="","",(BV20*DE$15)) -> 0.375 | DF20: =IF(CR20="","",(CR20*DF$15)) -> 0.3 | DG20: =IF(DD20="","",(DD20*DG$15)) -> 0.5 | DH20: =IF($DF$15="",IF(OR(DE20="",DG20="")=TRUE,"",(SUM(DE20:DG20))),IF(OR(DE20="",DF20="",DG20="")=TRUE,"",(SUM(DE20:DG20)))) -> 1.175 | DI20: =IF(DH20="","",LOOKUP(DH20,{0,1.1251,1.3751,1.6251,1.8751,2.1251,2.3751,2.6251,2.8751,3.1251,3.3751,3.6251},{"1.00","1.25","1.50","1.75","2.00","2.25","2.50","2.75","3.00","3.25","3.50","5.00"})) -> 1.25
E21: 4 | F21: =IF(NOT(ISBLANK('Midterm OVPAA-F-INS-055A RAW SC'!F21)),'Midterm OVPAA-F-INS-055A RAW SC'!F21,"") -> 2201105829 | G21: =IF(NOT(ISBLANK('Midterm OVPAA-F-INS-055A RAW SC'!G21)),'Midterm OVPAA-F-INS-055A RAW SC'!G21,"") -> De Guzman, Jim Dale Manong | H21: =IF('Midterm OVPAA-F-INS-055A RAW SC'!H21="","",'Midterm OVPAA-F-INS-055A RAW SC'!H21/'Midterm OVPAA-F-INS-055A RAW SC'!H$17*100) -> 72 | I21: =IF('Midterm OVPAA-F-INS-055A RAW SC'!I21="","",'Midterm OVPAA-F-INS-055A RAW SC'!I21/'Midterm OVPAA-F-INS-055A RAW SC'!I$17*100) -> 60 | J21: =IF('Midterm OVPAA-F-INS-055A RAW SC'!J21="","",'Midterm OVPAA-F-INS-055A RAW SC'!J21/'Midterm OVPAA-F-INS-055A RAW SC'!J$17*100) -> 0 | K21: =IF('Midterm OVPAA-F-INS-055A RAW SC'!K21="","",'Midterm OVPAA-F-INS-055A RAW SC'!K21/'Midterm OVPAA-F-INS-055A RAW SC'!K$17*100) | L21: =IF('Midterm OVPAA-F-INS-055A RAW SC'!L21="","",'Midterm OVPAA-F-INS-055A RAW SC'!L21/'Midterm OVPAA-F-INS-055A RAW SC'!L$17*100) | M21: =IF('Midterm OVPAA-F-INS-055A RAW SC'!M21="","",'Midterm OVPAA-F-INS-055A RAW SC'!M21/'Midterm OVPAA-F-INS-055A RAW SC'!M$17*100) | N21: =IF('Midterm OVPAA-F-INS-055A RAW SC'!N21="","",'Midterm OVPAA-F-INS-055A RAW SC'!N21/'Midterm OVPAA-F-INS-055A RAW SC'!N$17*100) | O21: =IF('Midterm OVPAA-F-INS-055A RAW SC'!O21="","",'Midterm OVPAA-F-INS-055A RAW SC'!O21/'Midterm OVPAA-F-INS-055A RAW SC'!O$17*100) | ... BT21: =IF('Midterm OVPAA-F-INS-055A RAW SC'!BT21="","",'Midterm OVPAA-F-INS-055A RAW SC'!BT21/'Midterm OVPAA-F-INS-055A RAW SC'!BT$17*100) | BU21: {=IF('Midterm OVPAA-F-INS-055A RAW SC'!$G21="","",IF((SUMPRODUCT(--ISBLANK('Midterm OVPAA-F-INS-055A RAW SC'!H21:BT21))=COLUMNS('Midterm OVPAA-F-INS-055A RAW SC'!H21:BT21))=TRUE,"",(((COUNTA('Midterm OVPAA-F-INS-055A RAW SC'!$H$17:$BT$17)+COUNTBLANK('Midterm OVPAA-F-INS-055A RAW SC'!H21:BT21))-COLUMNS('Midterm OVPAA-F-INS-055A RAW SC'!H21:BT21))*5+SUM(H21:BT21))/COUNTA('Midterm OVPAA-F-INS-055A RAW SC'!$H$17:$BT$17)))} -> 44 | BV21: =IF(BU21="","",VLOOKUP(BU21,IF('Midterm OVPAA-F-INS-055A RAW SC'!$V$12=0.5,TRANSMUTATION!$C$4:$D$17,TRANSMUTATION!$G$4:$H$17),2,TRUE)) -> 3.25 | BW21: =IF('Midterm OVPAA-F-INS-055A RAW SC'!BU21="","",'Midterm OVPAA-F-INS-055A RAW SC'!BU21/'Midterm OVPAA-F-INS-055A RAW SC'!BU$17*100) -> 72 | BX21: =IF('Midterm OVPAA-F-INS-055A RAW SC'!BV21="","",'Midterm OVPAA-F-INS-055A RAW SC'!BV21/'Midterm OVPAA-F-INS-055A RAW SC'!BV$17*100) -> 100 | BY21: =IF('Midterm OVPAA-F-INS-055A RAW SC'!BW21="","",'Midterm OVPAA-F-INS-055A RAW SC'!BW21/'Midterm OVPAA-F-INS-055A RAW SC'!BW$17*100) -> 75 | BZ21: =IF('Midterm OVPAA-F-INS-055A RAW SC'!BX21="","",'Midterm OVPAA-F-INS-055A RAW SC'!BX21/'Midterm OVPAA-F-INS-055A RAW SC'!BX$17*100) | CA21: =IF('Midterm OVPAA-F-INS-055A RAW SC'!BY21="","",'Midterm OVPAA-F-INS-055A RAW SC'!BY21/'Midterm OVPAA-F-INS-055A RAW SC'!BY$17*100) | CB21: =IF('Midterm OVPAA-F-INS-055A RAW SC'!BZ21="","",'Midterm OVPAA-F-INS-055A RAW SC'!BZ21/'Midterm OVPAA-F-INS-055A RAW SC'!BZ$17*100) | CC21: =IF('Midterm OVPAA-F-INS-055A RAW SC'!CA21="","",'Midterm OVPAA-F-INS-055A RAW SC'!CA21/'Midterm OVPAA-F-INS-055A RAW SC'!CA$17*100) | CD21: =IF('Midterm OVPAA-F-INS-055A RAW SC'!CB21="","",'Midterm OVPAA-F-INS-055A RAW SC'!CB21/'Midterm OVPAA-F-INS-055A RAW SC'!CB$17*100) | ... CP21: =IF('Midterm OVPAA-F-INS-055A RAW SC'!CN21="","",'Midterm OVPAA-F-INS-055A RAW SC'!CN21/'Midterm OVPAA-F-INS-055A RAW SC'!CN$17*100) | CQ21: {=IF('Midterm OVPAA-F-INS-055A RAW SC'!G21="","",IF((SUMPRODUCT(--ISBLANK('Midterm OVPAA-F-INS-055A RAW SC'!BU21:CN21))=COLUMNS('Midterm OVPAA-F-INS-055A RAW SC'!BU21:CN21))=TRUE,"",(((COUNTA('Midterm OVPAA-F-INS-055A RAW SC'!$BU$17:$CN$17)+COUNTBLANK('Midterm OVPAA-F-INS-055A RAW SC'!BU21:CN21))-COLUMNS('Midterm OVPAA-F-INS-055A RAW SC'!BU21:CN21))*5+SUM(BW21:CP21))/COUNTA('Midterm OVPAA-F-INS-055A RAW SC'!$BU$17:$CN$17)))} -> 82.333333 | CR21: =IF(CQ21="","",VLOOKUP(CQ21,IF('Midterm OVPAA-F-INS-055A RAW SC'!$V$12=0.5,TRANSMUTATION!$C$4:$D$17,TRANSMUTATION!$G$4:$H$17),2,TRUE)) -> 1.75 | CS21: =IF('Midterm OVPAA-F-INS-055A RAW SC'!CO21="","",'Midterm OVPAA-F-INS-055A RAW SC'!CO21/'Midterm OVPAA-F-INS-055A RAW SC'!CO$17*100) -> 72 | CT21: =IF('Midterm OVPAA-F-INS-055A RAW SC'!CP21="","",'Midterm OVPAA-F-INS-055A RAW SC'!CP21/'Midterm OVPAA-F-INS-055A RAW SC'!CP$17*100) -> 72 | CU21: =IF('Midterm OVPAA-F-INS-055A RAW SC'!CQ21="","",'Midterm OVPAA-F-INS-055A RAW SC'!CQ21/'Midterm OVPAA-F-INS-055A RAW SC'!CQ$17*100) | CV21: =IF('Midterm OVPAA-F-INS-055A RAW SC'!CR21="","",'Midterm OVPAA-F-INS-055A RAW SC'!CR21/'Midterm OVPAA-F-INS-055A RAW SC'!CR$17*100) | CW21: =IF('Midterm OVPAA-F-INS-055A RAW SC'!CS21="","",'Midterm OVPAA-F-INS-055A RAW SC'!CS21/'Midterm OVPAA-F-INS-055A RAW SC'!CS$17*100) | CX21: =IF('Midterm OVPAA-F-INS-055A RAW SC'!CT21="","",'Midterm OVPAA-F-INS-055A RAW SC'!CT21/'Midterm OVPAA-F-INS-055A RAW SC'!CT$17*100) | CY21: =IF('Midterm OVPAA-F-INS-055A RAW SC'!CU21="","",'Midterm OVPAA-F-INS-055A RAW SC'!CU21/'Midterm OVPAA-F-INS-055A RAW SC'!CU$17*100) | CZ21: =IF('Midterm OVPAA-F-INS-055A RAW SC'!CV21="","",'Midterm OVPAA-F-INS-055A RAW SC'!CV21/'Midterm OVPAA-F-INS-055A RAW SC'!CV$17*100) | ... DB21: =IF('Midterm OVPAA-F-INS-055A RAW SC'!CX21="","",'Midterm OVPAA-F-INS-055A RAW SC'!CX21/'Midterm OVPAA-F-INS-055A RAW SC'!CX$17*100) | DC21: {=IF('Midterm OVPAA-F-INS-055A RAW SC'!$G21="","",IF((SUMPRODUCT(--ISBLANK('Midterm OVPAA-F-INS-055A RAW SC'!CO21:CX21))=COLUMNS('Midterm OVPAA-F-INS-055A RAW SC'!CO21:CX21))=TRUE,"",(((COUNTA('Midterm OVPAA-F-INS-055A RAW SC'!$CO$17:$CX$17)+COUNTBLANK('Midterm OVPAA-F-INS-055A RAW SC'!CO21:CX21))-COLUMNS('Midterm OVPAA-F-INS-055A RAW SC'!CO21:CX21))*5+SUM(CS21:DB21))/COUNTA('Midterm OVPAA-F-INS-055A RAW SC'!$CO$17:$CX$17)))} -> 72 | DD21: =IF(DC21="","",VLOOKUP(DC21,IF('Midterm OVPAA-F-INS-055A RAW SC'!$V$12=0.5,TRANSMUTATION!$C$4:$D$17,TRANSMUTATION!$G$4:$H$17),2,TRUE)) -> 2.25 | DE21: =IF(BV21="","",(BV21*DE$15)) -> 0.975 | DF21: =IF(CR21="","",(CR21*DF$15)) -> 0.525 | DG21: =IF(DD21="","",(DD21*DG$15)) -> 0.9 | DH21: =IF($DF$15="",IF(OR(DE21="",DG21="")=TRUE,"",(SUM(DE21:DG21))),IF(OR(DE21="",DF21="",DG21="")=TRUE,"",(SUM(DE21:DG21)))) -> 2.4 | DI21: =IF(DH21="","",LOOKUP(DH21,{0,1.1251,1.3751,1.6251,1.8751,2.1251,2.3751,2.6251,2.8751,3.1251,3.3751,3.6251},{"1.00","1.25","1.50","1.75","2.00","2.25","2.50","2.75","3.00","3.25","3.50","5.00"})) -> 2.50
E22: 5 | F22: =IF(NOT(ISBLANK('Midterm OVPAA-F-INS-055A RAW SC'!F22)),'Midterm OVPAA-F-INS-055A RAW SC'!F22,"") -> 2201103056 | G22: =IF(NOT(ISBLANK('Midterm OVPAA-F-INS-055A RAW SC'!G22)),'Midterm OVPAA-F-INS-055A RAW SC'!G22,"") -> Dela Cerna, Johann Derek Javier | H22: =IF('Midterm OVPAA-F-INS-055A RAW SC'!H22="","",'Midterm OVPAA-F-INS-055A RAW SC'!H22/'Midterm OVPAA-F-INS-055A RAW SC'!H$17*100) -> 70 | I22: =IF('Midterm OVPAA-F-INS-055A RAW SC'!I22="","",'Midterm OVPAA-F-INS-055A RAW SC'!I22/'Midterm OVPAA-F-INS-055A RAW SC'!I$17*100) -> 92 | J22: =IF('Midterm OVPAA-F-INS-055A RAW SC'!J22="","",'Midterm OVPAA-F-INS-055A RAW SC'!J22/'Midterm OVPAA-F-INS-055A RAW SC'!J$17*100) -> 90 | K22: =IF('Midterm OVPAA-F-INS-055A RAW SC'!K22="","",'Midterm OVPAA-F-INS-055A RAW SC'!K22/'Midterm OVPAA-F-INS-055A RAW SC'!K$17*100) | L22: =IF('Midterm OVPAA-F-INS-055A RAW SC'!L22="","",'Midterm OVPAA-F-INS-055A RAW SC'!L22/'Midterm OVPAA-F-INS-055A RAW SC'!L$17*100) | M22: =IF('Midterm OVPAA-F-INS-055A RAW SC'!M22="","",'Midterm OVPAA-F-INS-055A RAW SC'!M22/'Midterm OVPAA-F-INS-055A RAW SC'!M$17*100) | N22: =IF('Midterm OVPAA-F-INS-055A RAW SC'!N22="","",'Midterm OVPAA-F-INS-055A RAW SC'!N22/'Midterm OVPAA-F-INS-055A RAW SC'!N$17*100) | O22: =IF('Midterm OVPAA-F-INS-055A RAW SC'!O22="","",'Midterm OVPAA-F-INS-055A RAW SC'!O22/'Midterm OVPAA-F-INS-055A RAW SC'!O$17*100) | ... BT22: =IF('Midterm OVPAA-F-INS-055A RAW SC'!BT22="","",'Midterm OVPAA-F-INS-055A RAW SC'!BT22/'Midterm OVPAA-F-INS-055A RAW SC'!BT$17*100) | BU22: {=IF('Midterm OVPAA-F-INS-055A RAW SC'!$G22="","",IF((SUMPRODUCT(--ISBLANK('Midterm OVPAA-F-INS-055A RAW SC'!H22:BT22))=COLUMNS('Midterm OVPAA-F-INS-055A RAW SC'!H22:BT22))=TRUE,"",(((COUNTA('Midterm OVPAA-F-INS-055A RAW SC'!$H$17:$BT$17)+COUNTBLANK('Midterm OVPAA-F-INS-055A RAW SC'!H22:BT22))-COLUMNS('Midterm OVPAA-F-INS-055A RAW SC'!H22:BT22))*5+SUM(H22:BT22))/COUNTA('Midterm OVPAA-F-INS-055A RAW SC'!$H$17:$BT$17)))} -> 84 | BV22: =IF(BU22="","",VLOOKUP(BU22,IF('Midterm OVPAA-F-INS-055A RAW SC'!$V$12=0.5,TRANSMUTATION!$C$4:$D$17,TRANSMUTATION!$G$4:$H$17),2,TRUE)) -> 1.75 | BW22: =IF('Midterm OVPAA-F-INS-055A RAW SC'!BU22="","",'Midterm OVPAA-F-INS-055A RAW SC'!BU22/'Midterm OVPAA-F-INS-055A RAW SC'!BU$17*100) -> 70 | BX22: =IF('Midterm OVPAA-F-INS-055A RAW SC'!BV22="","",'Midterm OVPAA-F-INS-055A RAW SC'!BV22/'Midterm OVPAA-F-INS-055A RAW SC'!BV$17*100) -> 100 | BY22: =IF('Midterm OVPAA-F-INS-055A RAW SC'!BW22="","",'Midterm OVPAA-F-INS-055A RAW SC'!BW22/'Midterm OVPAA-F-INS-055A RAW SC'!BW$17*100) -> 100 | BZ22: =IF('Midterm OVPAA-F-INS-055A RAW SC'!BX22="","",'Midterm OVPAA-F-INS-055A RAW SC'!BX22/'Midterm OVPAA-F-INS-055A RAW SC'!BX$17*100) | CA22: =IF('Midterm OVPAA-F-INS-055A RAW SC'!BY22="","",'Midterm OVPAA-F-INS-055A RAW SC'!BY22/'Midterm OVPAA-F-INS-055A RAW SC'!BY$17*100) | CB22: =IF('Midterm OVPAA-F-INS-055A RAW SC'!BZ22="","",'Midterm OVPAA-F-INS-055A RAW SC'!BZ22/'Midterm OVPAA-F-INS-055A RAW SC'!BZ$17*100) | CC22: =IF('Midterm OVPAA-F-INS-055A RAW SC'!CA22="","",'Midterm OVPAA-F-INS-055A RAW SC'!CA22/'Midterm OVPAA-F-INS-055A RAW SC'!CA$17*100) | CD22: =IF('Midterm OVPAA-F-INS-055A RAW SC'!CB22="","",'Midterm OVPAA-F-INS-055A RAW SC'!CB22/'Midterm OVPAA-F-INS-055A RAW SC'!CB$17*100) | ... CP22: =IF('Midterm OVPAA-F-INS-055A RAW SC'!CN22="","",'Midterm OVPAA-F-INS-055A RAW SC'!CN22/'Midterm OVPAA-F-INS-055A RAW SC'!CN$17*100) | CQ22: {=IF('Midterm OVPAA-F-INS-055A RAW SC'!G22="","",IF((SUMPRODUCT(--ISBLANK('Midterm OVPAA-F-INS-055A RAW SC'!BU22:CN22))=COLUMNS('Midterm OVPAA-F-INS-055A RAW SC'!BU22:CN22))=TRUE,"",(((COUNTA('Midterm OVPAA-F-INS-055A RAW SC'!$BU$17:$CN$17)+COUNTBLANK('Midterm OVPAA-F-INS-055A RAW SC'!BU22:CN22))-COLUMNS('Midterm OVPAA-F-INS-055A RAW SC'!BU22:CN22))*5+SUM(BW22:CP22))/COUNTA('Midterm OVPAA-F-INS-055A RAW SC'!$BU$17:$CN$17)))} -> 90 | CR22: =IF(CQ22="","",VLOOKUP(CQ22,IF('Midterm OVPAA-F-INS-055A RAW SC'!$V$12=0.5,TRANSMUTATION!$C$4:$D$17,TRANSMUTATION!$G$4:$H$17),2,TRUE)) -> 1.5 | CS22: =IF('Midterm OVPAA-F-INS-055A RAW SC'!CO22="","",'Midterm OVPAA-F-INS-055A RAW SC'!CO22/'Midterm OVPAA-F-INS-055A RAW SC'!CO$17*100) -> 76 | CT22: =IF('Midterm OVPAA-F-INS-055A RAW SC'!CP22="","",'Midterm OVPAA-F-INS-055A RAW SC'!CP22/'Midterm OVPAA-F-INS-055A RAW SC'!CP$17*100) -> 86 | CU22: =IF('Midterm OVPAA-F-INS-055A RAW SC'!CQ22="","",'Midterm OVPAA-F-INS-055A RAW SC'!CQ22/'Midterm OVPAA-F-INS-055A RAW SC'!CQ$17*100) | CV22: =IF('Midterm OVPAA-F-INS-055A RAW SC'!CR22="","",'Midterm OVPAA-F-INS-055A RAW SC'!CR22/'Midterm OVPAA-F-INS-055A RAW SC'!CR$17*100) | CW22: =IF('Midterm OVPAA-F-INS-055A RAW SC'!CS22="","",'Midterm OVPAA-F-INS-055A RAW SC'!CS22/'Midterm OVPAA-F-INS-055A RAW SC'!CS$17*100) | CX22: =IF('Midterm OVPAA-F-INS-055A RAW SC'!CT22="","",'Midterm OVPAA-F-INS-055A RAW SC'!CT22/'Midterm OVPAA-F-INS-055A RAW SC'!CT$17*100) | CY22: =IF('Midterm OVPAA-F-INS-055A RAW SC'!CU22="","",'Midterm OVPAA-F-INS-055A RAW SC'!CU22/'Midterm OVPAA-F-INS-055A RAW SC'!CU$17*100) | CZ22: =IF('Midterm OVPAA-F-INS-055A RAW SC'!CV22="","",'Midterm OVPAA-F-INS-055A RAW SC'!CV22/'Midterm OVPAA-F-INS-055A RAW SC'!CV$17*100) | ... DB22: =IF('Midterm OVPAA-F-INS-055A RAW SC'!CX22="","",'Midterm OVPAA-F-INS-055A RAW SC'!CX22/'Midterm OVPAA-F-INS-055A RAW SC'!CX$17*100) | DC22: {=IF('Midterm OVPAA-F-INS-055A RAW SC'!$G22="","",IF((SUMPRODUCT(--ISBLANK('Midterm OVPAA-F-INS-055A RAW SC'!CO22:CX22))=COLUMNS('Midterm OVPAA-F-INS-055A RAW SC'!CO22:CX22))=TRUE,"",(((COUNTA('Midterm OVPAA-F-INS-055A RAW SC'!$CO$17:$CX$17)+COUNTBLANK('Midterm OVPAA-F-INS-055A RAW SC'!CO22:CX22))-COLUMNS('Midterm OVPAA-F-INS-055A RAW SC'!CO22:CX22))*5+SUM(CS22:DB22))/COUNTA('Midterm OVPAA-F-INS-055A RAW SC'!$CO$17:$CX$17)))} -> 81 | DD22: =IF(DC22="","",VLOOKUP(DC22,IF('Midterm OVPAA-F-INS-055A RAW SC'!$V$12=0.5,TRANSMUTATION!$C$4:$D$17,TRANSMUTATION!$G$4:$H$17),2,TRUE)) -> 1.75 | DE22: =IF(BV22="","",(BV22*DE$15)) -> 0.525 | DF22: =IF(CR22="","",(CR22*DF$15)) -> 0.45 | DG22: =IF(DD22="","",(DD22*DG$15)) -> 0.7 | DH22: =IF($DF$15="",IF(OR(DE22="",DG22="")=TRUE,"",(SUM(DE22:DG22))),IF(OR(DE22="",DF22="",DG22="")=TRUE,"",(SUM(DE22:DG22)))) -> 1.675 | DI22: =IF(DH22="","",LOOKUP(DH22,{0,1.1251,1.3751,1.6251,1.8751,2.1251,2.3751,2.6251,2.8751,3.1251,3.3751,3.6251},{"1.00","1.25","1.50","1.75","2.00","2.25","2.50","2.75","3.00","3.25","3.50","5.00"})) -> 1.75
E23: 6 | F23: =IF(NOT(ISBLANK('Midterm OVPAA-F-INS-055A RAW SC'!F23)),'Midterm OVPAA-F-INS-055A RAW SC'!F23,"") -> 2201100446 | G23: =IF(NOT(ISBLANK('Midterm OVPAA-F-INS-055A RAW SC'!G23)),'Midterm OVPAA-F-INS-055A RAW SC'!G23,"") -> Delfin, Kyle Arnie Jopson | H23: =IF('Midterm OVPAA-F-INS-055A RAW SC'!H23="","",'Midterm OVPAA-F-INS-055A RAW SC'!H23/'Midterm OVPAA-F-INS-055A RAW SC'!H$17*100) -> 80 | I23: =IF('Midterm OVPAA-F-INS-055A RAW SC'!I23="","",'Midterm OVPAA-F-INS-055A RAW SC'!I23/'Midterm OVPAA-F-INS-055A RAW SC'!I$17*100) -> 94 | J23: =IF('Midterm OVPAA-F-INS-055A RAW SC'!J23="","",'Midterm OVPAA-F-INS-055A RAW SC'!J23/'Midterm OVPAA-F-INS-055A RAW SC'!J$17*100) -> 84 | K23: =IF('Midterm OVPAA-F-INS-055A RAW SC'!K23="","",'Midterm OVPAA-F-INS-055A RAW SC'!K23/'Midterm OVPAA-F-INS-055A RAW SC'!K$17*100) | L23: =IF('Midterm OVPAA-F-INS-055A RAW SC'!L23="","",'Midterm OVPAA-F-INS-055A RAW SC'!L23/'Midterm OVPAA-F-INS-055A RAW SC'!L$17*100) | M23: =IF('Midterm OVPAA-F-INS-055A RAW SC'!M23="","",'Midterm OVPAA-F-INS-055A RAW SC'!M23/'Midterm OVPAA-F-INS-055A RAW SC'!M$17*100) | N23: =IF('Midterm OVPAA-F-INS-055A RAW SC'!N23="","",'Midterm OVPAA-F-INS-055A RAW SC'!N23/'Midterm OVPAA-F-INS-055A RAW SC'!N$17*100) | O23: =IF('Midterm OVPAA-F-INS-055A RAW SC'!O23="","",'Midterm OVPAA-F-INS-055A RAW SC'!O23/'Midterm OVPAA-F-INS-055A RAW SC'!O$17*100) | ... BT23: =IF('Midterm OVPAA-F-INS-055A RAW SC'!BT23="","",'Midterm OVPAA-F-INS-055A RAW SC'!BT23/'Midterm OVPAA-F-INS-055A RAW SC'!BT$17*100) | BU23: {=IF('Midterm OVPAA-F-INS-055A RAW SC'!$G23="","",IF((SUMPRODUCT(--ISBLANK('Midterm OVPAA-F-INS-055A RAW SC'!H23:BT23))=COLUMNS('Midterm OVPAA-F-INS-055A RAW SC'!H23:BT23))=TRUE,"",(((COUNTA('Midterm OVPAA-F-INS-055A RAW SC'!$H$17:$BT$17)+COUNTBLANK('Midterm OVPAA-F-INS-055A RAW SC'!H23:BT23))-COLUMNS('Midterm OVPAA-F-INS-055A RAW SC'!H23:BT23))*5+SUM(H23:BT23))/COUNTA('Midterm OVPAA-F-INS-055A RAW SC'!$H$17:$BT$17)))} -> 86 | BV23: =IF(BU23="","",VLOOKUP(BU23,IF('Midterm OVPAA-F-INS-055A RAW SC'!$V$12=0.5,TRANSMUTATION!$C$4:$D$17,TRANSMUTATION!$G$4:$H$17),2,TRUE)) -> 1.5 | BW23: =IF('Midterm OVPAA-F-INS-055A RAW SC'!BU23="","",'Midterm OVPAA-F-INS-055A RAW SC'!BU23/'Midterm OVPAA-F-INS-055A RAW SC'!BU$17*100) -> 80 | BX23: =IF('Midterm OVPAA-F-INS-055A RAW SC'!BV23="","",'Midterm OVPAA-F-INS-055A RAW SC'!BV23/'Midterm OVPAA-F-INS-055A RAW SC'!BV$17*100) -> 100 | BY23: =IF('Midterm OVPAA-F-INS-055A RAW SC'!BW23="","",'Midterm OVPAA-F-INS-055A RAW SC'!BW23/'Midterm OVPAA-F-INS-055A RAW SC'!BW$17*100) -> 100 | BZ23: =IF('Midterm OVPAA-F-INS-055A RAW SC'!BX23="","",'Midterm OVPAA-F-INS-055A RAW SC'!BX23/'Midterm OVPAA-F-INS-055A RAW SC'!BX$17*100) | CA23: =IF('Midterm OVPAA-F-INS-055A RAW SC'!BY23="","",'Midterm OVPAA-F-INS-055A RAW SC'!BY23/'Midterm OVPAA-F-INS-055A RAW SC'!BY$17*100) | CB23: =IF('Midterm OVPAA-F-INS-055A RAW SC'!BZ23="","",'Midterm OVPAA-F-INS-055A RAW SC'!BZ23/'Midterm OVPAA-F-INS-055A RAW SC'!BZ$17*100) | CC23: =IF('Midterm OVPAA-F-INS-055A RAW SC'!CA23="","",'Midterm OVPAA-F-INS-055A RAW SC'!CA23/'Midterm OVPAA-F-INS-055A RAW SC'!CA$17*100) | CD23: =IF('Midterm OVPAA-F-INS-055A RAW SC'!CB23="","",'Midterm OVPAA-F-INS-055A RAW SC'!CB23/'Midterm OVPAA-F-INS-055A RAW SC'!CB$17*100) | ... CP23: =IF('Midterm OVPAA-F-INS-055A RAW SC'!CN23="","",'Midterm OVPAA-F-INS-055A RAW SC'!CN23/'Midterm OVPAA-F-INS-055A RAW SC'!CN$17*100) | CQ23: {=IF('Midterm OVPAA-F-INS-055A RAW SC'!G23="","",IF((SUMPRODUCT(--ISBLANK('Midterm OVPAA-F-INS-055A RAW SC'!BU23:CN23))=COLUMNS('Midterm OVPAA-F-INS-055A RAW SC'!BU23:CN23))=TRUE,"",(((COUNTA('Midterm OVPAA-F-INS-055A RAW SC'!$BU$17:$CN$17)+COUNTBLANK('Midterm OVPAA-F-INS-055A RAW SC'!BU23:CN23))-COLUMNS('Midterm OVPAA-F-INS-055A RAW SC'!BU23:CN23))*5+SUM(BW23:CP23))/COUNTA('Midterm OVPAA-F-INS-055A RAW SC'!$BU$17:$CN$17)))} -> 93.333333 | CR23: =IF(CQ23="","",VLOOKUP(CQ23,IF('Midterm OVPAA-F-INS-055A RAW SC'!$V$12=0.5,TRANSMUTATION!$C$4:$D$17,TRANSMUTATION!$G$4:$H$17),2,TRUE)) -> 1.25 | CS23: =IF('Midterm OVPAA-F-INS-055A RAW SC'!CO23="","",'Midterm OVPAA-F-INS-055A RAW SC'!CO23/'Midterm OVPAA-F-INS-055A RAW SC'!CO$17*100) -> 92 | CT23: =IF('Midterm OVPAA-F-INS-055A RAW SC'!CP23="","",'Midterm OVPAA-F-INS-055A RAW SC'!CP23/'Midterm OVPAA-F-INS-055A RAW SC'!CP$17*100) -> 80 | CU23: =IF('Midterm OVPAA-F-INS-055A RAW SC'!CQ23="","",'Midterm OVPAA-F-INS-055A RAW SC'!CQ23/'Midterm OVPAA-F-INS-055A RAW SC'!CQ$17*100) | CV23: =IF('Midterm OVPAA-F-INS-055A RAW SC'!CR23="","",'Midterm OVPAA-F-INS-055A RAW SC'!CR23/'Midterm OVPAA-F-INS-055A RAW SC'!CR$17*100) | CW23: =IF('Midterm OVPAA-F-INS-055A RAW SC'!CS23="","",'Midterm OVPAA-F-INS-055A RAW SC'!CS23/'Midterm OVPAA-F-INS-055A RAW SC'!CS$17*100) | CX23: =IF('Midterm OVPAA-F-INS-055A RAW SC'!CT23="","",'Midterm OVPAA-F-INS-055A RAW SC'!CT23/'Midterm OVPAA-F-INS-055A RAW SC'!CT$17*100) | CY23: =IF('Midterm OVPAA-F-INS-055A RAW SC'!CU23="","",'Midterm OVPAA-F-INS-055A RAW SC'!CU23/'Midterm OVPAA-F-INS-055A RAW SC'!CU$17*100) | CZ23: =IF('Midterm OVPAA-F-INS-055A RAW SC'!CV23="","",'Midterm OVPAA-F-INS-055A RAW SC'!CV23/'Midterm OVPAA-F-INS-055A RAW SC'!CV$17*100) | ... DB23: =IF('Midterm OVPAA-F-INS-055A RAW SC'!CX23="","",'Midterm OVPAA-F-INS-055A RAW SC'!CX23/'Midterm OVPAA-F-INS-055A RAW SC'!CX$17*100) | DC23: {=IF('Midterm OVPAA-F-INS-055A RAW SC'!$G23="","",IF((SUMPRODUCT(--ISBLANK('Midterm OVPAA-F-INS-055A RAW SC'!CO23:CX23))=COLUMNS('Midterm OVPAA-F-INS-055A RAW SC'!CO23:CX23))=TRUE,"",(((COUNTA('Midterm OVPAA-F-INS-055A RAW SC'!$CO$17:$CX$17)+COUNTBLANK('Midterm OVPAA-F-INS-055A RAW SC'!CO23:CX23))-COLUMNS('Midterm OVPAA-F-INS-055A RAW SC'!CO23:CX23))*5+SUM(CS23:DB23))/COUNTA('Midterm OVPAA-F-INS-055A RAW SC'!$CO$17:$CX$17)))} -> 86 | DD23: =IF(DC23="","",VLOOKUP(DC23,IF('Midterm OVPAA-F-INS-055A RAW SC'!$V$12=0.5,TRANSMUTATION!$C$4:$D$17,TRANSMUTATION!$G$4:$H$17),2,TRUE)) -> 1.5 | DE23: =IF(BV23="","",(BV23*DE$15)) -> 0.45 | DF23: =IF(CR23="","",(CR23*DF$15)) -> 0.375 | DG23: =IF(DD23="","",(DD23*DG$15)) -> 0.6 | DH23: =IF($DF$15="",IF(OR(DE23="",DG23="")=TRUE,"",(SUM(DE23:DG23))),IF(OR(DE23="",DF23="",DG23="")=TRUE,"",(SUM(DE23:DG23)))) -> 1.425 | DI23: =IF(DH23="","",LOOKUP(DH23,{0,1.1251,1.3751,1.6251,1.8751,2.1251,2.3751,2.6251,2.8751,3.1251,3.3751,3.6251},{"1.00","1.25","1.50","1.75","2.00","2.25","2.50","2.75","3.00","3.25","3.50","5.00"})) -> 1.50
E24: 7 | F24: =IF(NOT(ISBLANK('Midterm OVPAA-F-INS-055A RAW SC'!F24)),'Midterm OVPAA-F-INS-055A RAW SC'!F24,"") -> 1801101449 | G24: =IF(NOT(ISBLANK('Midterm OVPAA-F-INS-055A RAW SC'!G24)),'Midterm OVPAA-F-INS-055A RAW SC'!G24,"") -> Gumapac, Jannerie | H24: =IF('Midterm OVPAA-F-INS-055A RAW SC'!H24="","",'Midterm OVPAA-F-INS-055A RAW SC'!H24/'Midterm OVPAA-F-INS-055A RAW SC'!H$17*100) -> 72 | I24: =IF('Midterm OVPAA-F-INS-055A RAW SC'!I24="","",'Midterm OVPAA-F-INS-055A RAW SC'!I24/'Midterm OVPAA-F-INS-055A RAW SC'!I$17*100) -> 60 | J24: =IF('Midterm OVPAA-F-INS-055A RAW SC'!J24="","",'Midterm OVPAA-F-INS-055A RAW SC'!J24/'Midterm OVPAA-F-INS-055A RAW SC'!J$17*100) -> 100 | K24: =IF('Midterm OVPAA-F-INS-055A RAW SC'!K24="","",'Midterm OVPAA-F-INS-055A RAW SC'!K24/'Midterm OVPAA-F-INS-055A RAW SC'!K$17*100) | L24: =IF('Midterm OVPAA-F-INS-055A RAW SC'!L24="","",'Midterm OVPAA-F-INS-055A RAW SC'!L24/'Midterm OVPAA-F-INS-055A RAW SC'!L$17*100) | M24: =IF('Midterm OVPAA-F-INS-055A RAW SC'!M24="","",'Midterm OVPAA-F-INS-055A RAW SC'!M24/'Midterm OVPAA-F-INS-055A RAW SC'!M$17*100) | N24: =IF('Midterm OVPAA-F-INS-055A RAW SC'!N24="","",'Midterm OVPAA-F-INS-055A RAW SC'!N24/'Midterm OVPAA-F-INS-055A RAW SC'!N$17*100) | O24: =IF('Midterm OVPAA-F-INS-055A RAW SC'!O24="","",'Midterm OVPAA-F-INS-055A RAW SC'!O24/'Midterm OVPAA-F-INS-055A RAW SC'!O$17*100) | ... BT24: =IF('Midterm OVPAA-F-INS-055A RAW SC'!BT24="","",'Midterm OVPAA-F-INS-055A RAW SC'!BT24/'Midterm OVPAA-F-INS-055A RAW SC'!BT$17*100) | BU24: {=IF('Midterm OVPAA-F-INS-055A RAW SC'!$G24="","",IF((SUMPRODUCT(--ISBLANK('Midterm OVPAA-F-INS-055A RAW SC'!H24:BT24))=COLUMNS('Midterm OVPAA-F-INS-055A RAW SC'!H24:BT24))=TRUE,"",(((COUNTA('Midterm OVPAA-F-INS-055A RAW SC'!$H$17:$BT$17)+COUNTBLANK('Midterm OVPAA-F-INS-055A RAW SC'!H24:BT24))-COLUMNS('Midterm OVPAA-F-INS-055A RAW SC'!H24:BT24))*5+SUM(H24:BT24))/COUNTA('Midterm OVPAA-F-INS-055A RAW SC'!$H$17:$BT$17)))} -> 77.333333 | BV24: =IF(BU24="","",VLOOKUP(BU24,IF('Midterm OVPAA-F-INS-055A RAW SC'!$V$12=0.5,TRANSMUTATION!$C$4:$D$17,TRANSMUTATION!$G$4:$H$17),2,TRUE)) -> 2 | BW24: =IF('Midterm OVPAA-F-INS-055A RAW SC'!BU24="","",'Midterm OVPAA-F-INS-055A RAW SC'!BU24/'Midterm OVPAA-F-INS-055A RAW SC'!BU$17*100) -> 72 | BX24: =IF('Midterm OVPAA-F-INS-055A RAW SC'!BV24="","",'Midterm OVPAA-F-INS-055A RAW SC'!BV24/'Midterm OVPAA-F-INS-055A RAW SC'!BV$17*100) -> 100 | BY24: =IF('Midterm OVPAA-F-INS-055A RAW SC'!BW24="","",'Midterm OVPAA-F-INS-055A RAW SC'!BW24/'Midterm OVPAA-F-INS-055A RAW SC'!BW$17*100) -> 80 | BZ24: =IF('Midterm OVPAA-F-INS-055A RAW SC'!BX24="","",'Midterm OVPAA-F-INS-055A RAW SC'!BX24/'Midterm OVPAA-F-INS-055A RAW SC'!BX$17*100) | CA24: =IF('Midterm OVPAA-F-INS-055A RAW SC'!BY24="","",'Midterm OVPAA-F-INS-055A RAW SC'!BY24/'Midterm OVPAA-F-INS-055A RAW SC'!BY$17*100) | CB24: =IF('Midterm OVPAA-F-INS-055A RAW SC'!BZ24="","",'Midterm OVPAA-F-INS-055A RAW SC'!BZ24/'Midterm OVPAA-F-INS-055A RAW SC'!BZ$17*100) | CC24: =IF('Midterm OVPAA-F-INS-055A RAW SC'!CA24="","",'Midterm OVPAA-F-INS-055A RAW SC'!CA24/'Midterm OVPAA-F-INS-055A RAW SC'!CA$17*100) | CD24: =IF('Midterm OVPAA-F-INS-055A RAW SC'!CB24="","",'Midterm OVPAA-F-INS-055A RAW SC'!CB24/'Midterm OVPAA-F-INS-055A RAW SC'!CB$17*100) | ... CP24: =IF('Midterm OVPAA-F-INS-055A RAW SC'!CN24="","",'Midterm OVPAA-F-INS-055A RAW SC'!CN24/'Midterm OVPAA-F-INS-055A RAW SC'!CN$17*100) | CQ24: {=IF('Midterm OVPAA-F-INS-055A RAW SC'!G24="","",IF((SUMPRODUCT(--ISBLANK('Midterm OVPAA-F-INS-055A RAW SC'!BU24:CN24))=COLUMNS('Midterm OVPAA-F-INS-055A RAW SC'!BU24:CN24))=TRUE,"",(((COUNTA('Midterm OVPAA-F-INS-055A RAW SC'!$BU$17:$CN$17)+COUNTBLANK('Midterm OVPAA-F-INS-055A RAW SC'!BU24:CN24))-COLUMNS('Midterm OVPAA-F-INS-055A RAW SC'!BU24:CN24))*5+SUM(BW24:CP24))/COUNTA('Midterm OVPAA-F-INS-055A RAW SC'!$BU$17:$CN$17)))} -> 84 | CR24: =IF(CQ24="","",VLOOKUP(CQ24,IF('Midterm OVPAA-F-INS-055A RAW SC'!$V$12=0.5,TRANSMUTATION!$C$4:$D$17,TRANSMUTATION!$G$4:$H$17),2,TRUE)) -> 1.75 | CS24: =IF('Midterm OVPAA-F-INS-055A RAW SC'!CO24="","",'Midterm OVPAA-F-INS-055A RAW SC'!CO24/'Midterm OVPAA-F-INS-055A RAW SC'!CO$17*100) -> 72 | CT24: =IF('Midterm OVPAA-F-INS-055A RAW SC'!CP24="","",'Midterm OVPAA-F-INS-055A RAW SC'!CP24/'Midterm OVPAA-F-INS-055A RAW SC'!CP$17*100) -> 70 | CU24: =IF('Midterm OVPAA-F-INS-055A RAW SC'!CQ24="","",'Midterm OVPAA-F-INS-055A RAW SC'!CQ24/'Midterm OVPAA-F-INS-055A RAW SC'!CQ$17*100) | CV24: =IF('Midterm OVPAA-F-INS-055A RAW SC'!CR24="","",'Midterm OVPAA-F-INS-055A RAW SC'!CR24/'Midterm OVPAA-F-INS-055A RAW SC'!CR$17*100) | CW24: =IF('Midterm OVPAA-F-INS-055A RAW SC'!CS24="","",'Midterm OVPAA-F-INS-055A RAW SC'!CS24/'Midterm OVPAA-F-INS-055A RAW SC'!CS$17*100) | CX24: =IF('Midterm OVPAA-F-INS-055A RAW SC'!CT24="","",'Midterm OVPAA-F-INS-055A RAW SC'!CT24/'Midterm OVPAA-F-INS-055A RAW SC'!CT$17*100) | CY24: =IF('Midterm OVPAA-F-INS-055A RAW SC'!CU24="","",'Midterm OVPAA-F-INS-055A RAW SC'!CU24/'Midterm OVPAA-F-INS-055A RAW SC'!CU$17*100) | CZ24: =IF('Midterm OVPAA-F-INS-055A RAW SC'!CV24="","",'Midterm OVPAA-F-INS-055A RAW SC'!CV24/'Midterm OVPAA-F-INS-055A RAW SC'!CV$17*100) | ... DB24: =IF('Midterm OVPAA-F-INS-055A RAW SC'!CX24="","",'Midterm OVPAA-F-INS-055A RAW SC'!CX24/'Midterm OVPAA-F-INS-055A RAW SC'!CX$17*100) | DC24: {=IF('Midterm OVPAA-F-INS-055A RAW SC'!$G24="","",IF((SUMPRODUCT(--ISBLANK('Midterm OVPAA-F-INS-055A RAW SC'!CO24:CX24))=COLUMNS('Midterm OVPAA-F-INS-055A RAW SC'!CO24:CX24))=TRUE,"",(((COUNTA('Midterm OVPAA-F-INS-055A RAW SC'!$CO$17:$CX$17)+COUNTBLANK('Midterm OVPAA-F-INS-055A RAW SC'!CO24:CX24))-COLUMNS('Midterm OVPAA-F-INS-055A RAW SC'!CO24:CX24))*5+SUM(CS24:DB24))/COUNTA('Midterm OVPAA-F-INS-055A RAW SC'!$CO$17:$CX$17)))} -> 71 | DD24: =IF(DC24="","",VLOOKUP(DC24,IF('Midterm OVPAA-F-INS-055A RAW SC'!$V$12=0.5,TRANSMUTATION!$C$4:$D$17,TRANSMUTATION!$G$4:$H$17),2,TRUE)) -> 2.25 | DE24: =IF(BV24="","",(BV24*DE$15)) -> 0.6 | DF24: =IF(CR24="","",(CR24*DF$15)) -> 0.525 | DG24: =IF(DD24="","",(DD24*DG$15)) -> 0.9 | DH24: =IF($DF$15="",IF(OR(DE24="",DG24="")=TRUE,"",(SUM(DE24:DG24))),IF(OR(DE24="",DF24="",DG24="")=TRUE,"",(SUM(DE24:DG24)))) -> 2.025 | DI24: =IF(DH24="","",LOOKUP(DH24,{0,1.1251,1.3751,1.6251,1.8751,2.1251,2.3751,2.6251,2.8751,3.1251,3.3751,3.6251},{"1.00","1.25","1.50","1.75","2.00","2.25","2.50","2.75","3.00","3.25","3.50","5.00"})) -> 2.00
